
java; task2; test 0

stdout:

stderr:
Error encountered while running oracle
Traceback (most recent call last):
  File "sat_oracle.py", line 53, in <module>
    solve_sat(sys.argv[1], sys.argv[2])
  File "sat_oracle.py", line 39, in solve_sat
    with open(input_file) as f:
FileNotFoundError: [Errno 2] No such file or directory: 'sat_in/task2/00.cnf'


========================================


java; task2; test 1

stdout:

stderr:
Error encountered while running oracle
Traceback (most recent call last):
  File "sat_oracle.py", line 53, in <module>
    solve_sat(sys.argv[1], sys.argv[2])
  File "sat_oracle.py", line 39, in solve_sat
    with open(input_file) as f:
FileNotFoundError: [Errno 2] No such file or directory: 'sat_in/task2/01.cnf'


========================================

