
java; task2; test 0

stdout:

stderr:
Error encountered while running oracle
Traceback (most recent call last):
  File "sat_oracle.py", line 53, in <module>
    solve_sat(sys.argv[1], sys.argv[2])
  File "sat_oracle.py", line 39, in solve_sat
    with open(input_file) as f:
FileNotFoundError: [Errno 2] No such file or directory: 'sat_in/task2/00.cnf'


========================================


java; task2; test 1

stdout:

stderr:
Error encountered while running oracle
Traceback (most recent call last):
  File "sat_oracle.py", line 53, in <module>
    solve_sat(sys.argv[1], sys.argv[2])
  File "sat_oracle.py", line 39, in solve_sat
    with open(input_file) as f:
FileNotFoundError: [Errno 2] No such file or directory: 'sat_in/task2/01.cnf'


========================================


java; task2; test 2

stdout:

stderr:
Error encountered while running oracle
Traceback (most recent call last):
  File "sat_oracle.py", line 53, in <module>
    solve_sat(sys.argv[1], sys.argv[2])
  File "sat_oracle.py", line 39, in solve_sat
    with open(input_file) as f:
FileNotFoundError: [Errno 2] No such file or directory: 'sat_in/task2/02.cnf'


========================================


java; task2; test 3

stdout:

stderr:
Error encountered while running oracle
Traceback (most recent call last):
  File "sat_oracle.py", line 53, in <module>
    solve_sat(sys.argv[1], sys.argv[2])
  File "sat_oracle.py", line 39, in solve_sat
    with open(input_file) as f:
FileNotFoundError: [Errno 2] No such file or directory: 'sat_in/task2/03.cnf'


========================================


java; task2; test 4

stdout:

stderr:
Error encountered while running oracle
Traceback (most recent call last):
  File "sat_oracle.py", line 53, in <module>
    solve_sat(sys.argv[1], sys.argv[2])
  File "sat_oracle.py", line 39, in solve_sat
    with open(input_file) as f:
FileNotFoundError: [Errno 2] No such file or directory: 'sat_in/task2/04.cnf'


========================================


java; task2; test 5

stdout:

stderr:
Error encountered while running oracle
Traceback (most recent call last):
  File "sat_oracle.py", line 53, in <module>
    solve_sat(sys.argv[1], sys.argv[2])
  File "sat_oracle.py", line 39, in solve_sat
    with open(input_file) as f:
FileNotFoundError: [Errno 2] No such file or directory: 'sat_in/task2/05.cnf'


========================================


java; task2; test 6

stdout:

stderr:
Error encountered while running oracle
Traceback (most recent call last):
  File "sat_oracle.py", line 53, in <module>
    solve_sat(sys.argv[1], sys.argv[2])
  File "sat_oracle.py", line 39, in solve_sat
    with open(input_file) as f:
FileNotFoundError: [Errno 2] No such file or directory: 'sat_in/task2/06.cnf'


========================================


java; task2; test 7

stdout:

stderr:
Error encountered while running oracle
Traceback (most recent call last):
  File "sat_oracle.py", line 53, in <module>
    solve_sat(sys.argv[1], sys.argv[2])
  File "sat_oracle.py", line 39, in solve_sat
    with open(input_file) as f:
FileNotFoundError: [Errno 2] No such file or directory: 'sat_in/task2/07.cnf'


========================================


java; task2; test 8

stdout:

stderr:
Error encountered while running oracle
Traceback (most recent call last):
  File "sat_oracle.py", line 53, in <module>
    solve_sat(sys.argv[1], sys.argv[2])
  File "sat_oracle.py", line 39, in solve_sat
    with open(input_file) as f:
FileNotFoundError: [Errno 2] No such file or directory: 'sat_in/task2/08.cnf'


========================================


java; task2; test 9

stdout:

stderr:
Error encountered while running oracle
Traceback (most recent call last):
  File "sat_oracle.py", line 53, in <module>
    solve_sat(sys.argv[1], sys.argv[2])
  File "sat_oracle.py", line 39, in solve_sat
    with open(input_file) as f:
FileNotFoundError: [Errno 2] No such file or directory: 'sat_in/task2/09.cnf'


========================================


java; task2; test 10

stdout:

stderr:
Error encountered while running oracle
Traceback (most recent call last):
  File "sat_oracle.py", line 53, in <module>
    solve_sat(sys.argv[1], sys.argv[2])
  File "sat_oracle.py", line 39, in solve_sat
    with open(input_file) as f:
FileNotFoundError: [Errno 2] No such file or directory: 'sat_in/task2/10.cnf'


========================================


java; task2; test 11

stdout:

stderr:
Error encountered while running oracle
Traceback (most recent call last):
  File "sat_oracle.py", line 53, in <module>
    solve_sat(sys.argv[1], sys.argv[2])
  File "sat_oracle.py", line 39, in solve_sat
    with open(input_file) as f:
FileNotFoundError: [Errno 2] No such file or directory: 'sat_in/task2/11.cnf'


========================================

